Workbook

Sheet Instruções
A1: MATRIZ SWOT DO PERFIL ECONÔMICO-PRODUTIVO SETORIAL MUNICIPAL (PESM) — PANTANAL NORTE
A2: Projeto DSIP-MT | Convênio 984799/2025-SUDECO-UNEMAT | Meta 1 — Análise Diagnóstica Estratégica do PESM
A4: LÓGICA | B4: Estrutura adaptada da Matriz ICS-MP: indicador → limiares → classificação automática → síntese. Forças e Fraquezas vêm de indicadores INTERNOS (aba 'Indicadores (F-W)'), classificados automaticamente. Oportunidades e Ameaças vêm de fatores EXTERNOS (aba 'Fatores Externos (O-A)'), pontuados pela equipe com base nas pesquisas secundária, web-based e de campo.
A5: PASSO 1 | B5: Na aba 'Parâmetros', revise as bandas de tolerância e o corte de relevância dos fatores externos.
A6: PASSO 2 | B6: Na aba 'Indicadores (F-W)', preencha a coluna 'Valor ref. MT' (valor do estado no mesmo ano) e, para cada município, a coluna 'Dado bruto'. Células com fundo AMARELO e texto AZUL são de entrada manual. A coluna 'Classificação' é automática — não editar.
A7: CRITÉRIOS | B7: Absoluto: usa os limiares manuais (colunas J e K). Razão MT: limiares = ref. MT × (1 ± banda relativa). Dif. MT (p.p.): limiares = ref. MT ± banda em pontos percentuais (usar para taxas de variação e percentuais). Sentido '+': valor acima do limiar superior = Força; abaixo do inferior = Fraqueza. Sentido '-': o inverso. Entre os limiares = Neutro.
A8: PASSO 3 | B8: Na aba 'Fatores Externos (O-A)', atribua a cada fator a intensidade para cada município: 0 = não se aplica, 1 = baixa, 2 = média, 3 = alta. Registre a evidência que sustenta a nota (notícia, dado, observação de campo). Recomenda-se nota por consenso de dois pesquisadores.
A9: PASSO 4 | B9: Cada município tem sua própria aba 'SWOT - <município>', pronta para impressão em A4 paisagem e atualizada automaticamente. A aba 'Matriz SWOT (seletor)' permite alternar entre municípios na célula C3. A aba 'Painel' mostra a síntese dos 13 municípios e a frequência de cada item na região (base para a SWOT regional do Relatório Parcial).
A10: ÁREAS-CHAVE | B10: Quatro áreas-chave, dentro do intervalo de 3 a 6 previsto no Plano de Trabalho: Agropecuária; Indústria; Comércio e Serviços; Estrutura Econômica e Fiscal. Indicadores e fatores podem ser incluídos ao final das tabelas, desde que as fórmulas sejam estendidas.
A11: DADO AUSENTE | B11: Deixe a célula em branco. O indicador é contado como 'sem dado' e não entra em nenhum quadrante.
A12: CUIDADOS | B12: (1) Use o mesmo ano-base para todos os municípios em cada indicador. (2) RAIS capta apenas emprego formal e subestima a agropecuária; confrontar com VAB e Censo Agro. (3) Em municípios pequenos, QL e variações percentuais são instáveis; conferir valores absolutos. (4) Rondonópolis tem escala muito superior aos demais; em comparações regionais, apresentar resultados com e sem o município.
A13: LIMIARES | B13: Os limiares absolutos dos quocientes locacionais (0,8 e 1,2) e as bandas padrão (±10% e ±2 p.p.) são propostas iniciais, a validar com a coordenação e o orientador antes da análise final.
A14: RANKINGS | B14: 'Ranking Locacional': QLs, coeficiente de especialização e diversificação, calculados e ordenados automaticamente. 'Ranking SWOT (provisório)': índice (F−W)/n combinado com (O−T)/n; marcado como provisório até 75% de cobertura interna e externa.

Sheet Matriz SWOT (seletor)
B1: MATRIZ SWOT — PERFIL ECONÔMICO-PRODUTIVO SETORIAL MUNICIPAL (PESM) | PANTANAL NORTE
B3: Município: | C3: Cáceres | F3: ="Indicadores: "&COUNTIF(Aux!$C$6:$C$21,"Neutro")&" neutros | "&(COUNTA(Aux!$A$6:$A$21)-COUNTIF(Aux!$C$6:$C$21,"Força")-COUNTIF(Aux!$C$6:$C$21,"Fraqueza")-COUNTIF(Aux!$C$6:$C$21,"Neutro"))&" sem dado" -> Indicadores: 3 neutros | 2 sem dado
B5: FAVORÁVEL | F5: DESFAVORÁVEL
B6: ="FORÇAS (S) — "&COUNTIF(Aux!$C$6:$C$21,"Força")&" item(ns)" -> FORÇAS (S) — 3 item(ns) | F6: ="FRAQUEZAS (W) — "&COUNTIF(Aux!$C$6:$C$21,"Fraqueza")&" item(ns)" -> FRAQUEZAS (W) — 8 item(ns)
B7: Nº | C7: Item (área-chave, código e descrição) | D7: Valor | F7: Nº | G7: Item (área-chave, código e descrição) | H7: Valor
A8: AMBIENTE INTERNO | B8: =IF(C8="","",1) -> 1 | C8: =IFERROR(INDEX(Aux!$B$6:$B$21,MATCH(1,Aux!$E$6:$E$21,0)),"") -> [Agropecuária] AGR-03 – Variação do efetivo bovino em 5 anos (%) | D8: =IFERROR(INDEX(Aux!$D$6:$D$21,MATCH(1,Aux!$E$6:$E$21,0)),"") -> 22.65 | F8: =IF(G8="","",1) -> 1 | G8: =IFERROR(INDEX(Aux!$B$6:$B$21,MATCH(1,Aux!$F$6:$F$21,0)),"") -> [Agropecuária] AGR-01 – Quociente locacional do VAB agropecuário (base MT) (índice) | H8: =IFERROR(INDEX(Aux!$D$6:$D$21,MATCH(1,Aux!$F$6:$F$21,0)),"") -> 0.3713
B9: =IF(C9="","",2) -> 2 | C9: =IFERROR(INDEX(Aux!$B$6:$B$21,MATCH(2,Aux!$E$6:$E$21,0)),"") -> [Indústria] IND-02 – Variação do emprego formal na indústria em 5 anos (%) | D9: =IFERROR(INDEX(Aux!$D$6:$D$21,MATCH(2,Aux!$E$6:$E$21,0)),"") -> 58.91 | F9: =IF(G9="","",2) -> 2 | G9: =IFERROR(INDEX(Aux!$B$6:$B$21,MATCH(2,Aux!$F$6:$F$21,0)),"") -> [Indústria] IND-01 – Quociente locacional do VAB industrial (base MT) (índice) | H9: =IFERROR(INDEX(Aux!$D$6:$D$21,MATCH(2,Aux!$F$6:$F$21,0)),"") -> 0.6374
B10: =IF(C10="","",3) -> 3 | C10: =IFERROR(INDEX(Aux!$B$6:$B$21,MATCH(3,Aux!$E$6:$E$21,0)),"") -> [Comércio e Serviços] CS-01 – Quociente locacional do VAB de serviços, exceto adm. pública (base MT) (índice) | D10: =IFERROR(INDEX(Aux!$D$6:$D$21,MATCH(3,Aux!$E$6:$E$21,0)),"") -> 1.3013 | F10: =IF(G10="","",3) -> 3 | G10: =IFERROR(INDEX(Aux!$B$6:$B$21,MATCH(3,Aux!$F$6:$F$21,0)),"") -> [Indústria] IND-03 – Remuneração média do emprego formal industrial (R$) | H10: =IFERROR(INDEX(Aux!$D$6:$D$21,MATCH(3,Aux!$F$6:$F$21,0)),"") -> 2345.65
B11: =IF(C11="","",4) | C11: =IFERROR(INDEX(Aux!$B$6:$B$21,MATCH(4,Aux!$E$6:$E$21,0)),"") | D11: =IFERROR(INDEX(Aux!$D$6:$D$21,MATCH(4,Aux!$E$6:$E$21,0)),"") | F11: =IF(G11="","",4) -> 4 | G11: =IFERROR(INDEX(Aux!$B$6:$B$21,MATCH(4,Aux!$F$6:$F$21,0)),"") -> [Comércio e Serviços] CS-02 – Variação do emprego formal em comércio e serviços em 5 anos (%) | H11: =IFERROR(INDEX(Aux!$D$6:$D$21,MATCH(4,Aux!$F$6:$F$21,0)),"") -> 13.05
B12: =IF(C12="","",5) | C12: =IFERROR(INDEX(Aux!$B$6:$B$21,MATCH(5,Aux!$E$6:$E$21,0)),"") | D12: =IFERROR(INDEX(Aux!$D$6:$D$21,MATCH(5,Aux!$E$6:$E$21,0)),"") | F12: =IF(G12="","",5) -> 5 | G12: =IFERROR(INDEX(Aux!$B$6:$B$21,MATCH(5,Aux!$F$6:$F$21,0)),"") -> [Comércio e Serviços] CS-03 – Empresas e outras organizações ativas por mil habitantes (un./mil hab.) | H12: =IFERROR(INDEX(Aux!$D$6:$D$21,MATCH(5,Aux!$F$6:$F$21,0)),"") -> 19.41
B13: =IF(C13="","",6) | C13: =IFERROR(INDEX(Aux!$B$6:$B$21,MATCH(6,Aux!$E$6:$E$21,0)),"") | D13: =IFERROR(INDEX(Aux!$D$6:$D$21,MATCH(6,Aux!$E$6:$E$21,0)),"") | F13: =IF(G13="","",6) -> 6 | G13: =IFERROR(INDEX(Aux!$B$6:$B$21,MATCH(6,Aux!$F$6:$F$21,0)),"") -> [Estrutura Econômica e Fiscal] EST-01 – PIB per capita (R$) | H13: =IFERROR(INDEX(Aux!$D$6:$D$21,MATCH(6,Aux!$F$6:$F$21,0)),"") -> 31174.15
B14: =IF(C14="","",7) | C14: =IFERROR(INDEX(Aux!$B$6:$B$21,MATCH(7,Aux!$E$6:$E$21,0)),"") | D14: =IFERROR(INDEX(Aux!$D$6:$D$21,MATCH(7,Aux!$E$6:$E$21,0)),"") | F14: =IF(G14="","",7) -> 7 | G14: =IFERROR(INDEX(Aux!$B$6:$B$21,MATCH(7,Aux!$F$6:$F$21,0)),"") -> [Estrutura Econômica e Fiscal] EST-02 – Participação da administração pública no VAB total (%) | H14: =IFERROR(INDEX(Aux!$D$6:$D$21,MATCH(7,Aux!$F$6:$F$21,0)),"") -> 30.82
B15: =IF(C15="","",8) | C15: =IFERROR(INDEX(Aux!$B$6:$B$21,MATCH(8,Aux!$E$6:$E$21,0)),"") | D15: =IFERROR(INDEX(Aux!$D$6:$D$21,MATCH(8,Aux!$E$6:$E$21,0)),"") | F15: =IF(G15="","",8) -> 8 | G15: =IFERROR(INDEX(Aux!$B$6:$B$21,MATCH(8,Aux!$F$6:$F$21,0)),"") -> [Estrutura Econômica e Fiscal] EST-03 – Vínculos formais por 100 habitantes (vínculos/100 hab.) | H15: =IFERROR(INDEX(Aux!$D$6:$D$21,MATCH(8,Aux!$F$6:$F$21,0)),"") -> 18.4
B16: =IF(C16="","",9) | C16: =IFERROR(INDEX(Aux!$B$6:$B$21,MATCH(9,Aux!$E$6:$E$21,0)),"") | D16: =IFERROR(INDEX(Aux!$D$6:$D$21,MATCH(9,Aux!$E$6:$E$21,0)),"") | F16: =IF(G16="","",9) | G16: =IFERROR(INDEX(Aux!$B$6:$B$21,MATCH(9,Aux!$F$6:$F$21,0)),"") | H16: =IFERROR(INDEX(Aux!$D$6:$D$21,MATCH(9,Aux!$F$6:$F$21,0)),"")
B17: =IF(C17="","",10) | C17: =IFERROR(INDEX(Aux!$B$6:$B$21,MATCH(10,Aux!$E$6:$E$21,0)),"") | D17: =IFERROR(INDEX(Aux!$D$6:$D$21,MATCH(10,Aux!$E$6:$E$21,0)),"") | F17: =IF(G17="","",10) | G17: =IFERROR(INDEX(Aux!$B$6:$B$21,MATCH(10,Aux!$F$6:$F$21,0)),"") | H17: =IFERROR(INDEX(Aux!$D$6:$D$21,MATCH(10,Aux!$F$6:$F$21,0)),"")
B18: =IF(C18="","",11) | C18: =IFERROR(INDEX(Aux!$B$6:$B$21,MATCH(11,Aux!$E$6:$E$21,0)),"") | D18: =IFERROR(INDEX(Aux!$D$6:$D$21,MATCH(11,Aux!$E$6:$E$21,0)),"") | F18: =IF(G18="","",11) | G18: =IFERROR(INDEX(Aux!$B$6:$B$21,MATCH(11,Aux!$F$6:$F$21,0)),"") | H18: =IFERROR(INDEX(Aux!$D$6:$D$21,MATCH(11,Aux!$F$6:$F$21,0)),"")
B19: =IF(C19="","",12) | C19: =IFERROR(INDEX(Aux!$B$6:$B$21,MATCH(12,Aux!$E$6:$E$21,0)),"") | D19: =IFERROR(INDEX(Aux!$D$6:$D$21,MATCH(12,Aux!$E$6:$E$21,0)),"") | F19: =IF(G19="","",12) | G19: =IFERROR(INDEX(Aux!$B$6:$B$21,MATCH(12,Aux!$F$6:$F$21,0)),"") | H19: =IFERROR(INDEX(Aux!$D$6:$D$21,MATCH(12,Aux!$F$6:$F$21,0)),"")
C20: =IF(COUNTIF(Aux!$C$6:$C$21,"Força")>12,"+ "&(COUNTIF(Aux!$C$6:$C$21,"Força")-12)&" item(ns) não exibido(s) — ver abas de dados","") | G20: =IF(COUNTIF(Aux!$C$6:$C$21,"Fraqueza")>12,"+ "&(COUNTIF(Aux!$C$6:$C$21,"Fraqueza")-12)&" item(ns) não exibido(s) — ver abas de dados","")
B22: ="OPORTUNIDADES (O) — "&SUM(Aux!$L$6:$L$16)&" item(ns)" -> OPORTUNIDADES (O) — 6 item(ns) | F22: ="AMEAÇAS (T) — "&SUM(Aux!$N$6:$N$16)&" item(ns)" -> AMEAÇAS (T) — 4 item(ns)
B23: Nº | C23: Item (área-chave, código e descrição) | D23: Intensidade | F23: Nº | G23: Item (área-chave, código e descrição) | H23: Intensidade
A24: AMBIENTE EXTERNO | B24: =IF(C24="","",1) -> 1 | C24: =IFERROR(INDEX(Aux!$I$6:$I$16,MATCH(1,Aux!$M$6:$M$16,0)),"") -> [Agropecuária] OP-01 – Demanda externa por carne bovina e proteína animal | D24: =IFERROR(INDEX(Aux!$K$6:$K$16,MATCH(1,Aux!$M$6:$M$16,0)),"") -> 3 | F24: =IF(G24="","",1) -> 1 | G24: =IFERROR(INDEX(Aux!$I$6:$I$16,MATCH(1,Aux!$O$6:$O$16,0)),"") -> [Agropecuária] AM-01 – Eventos climáticos extremos: secas prolongadas e incêndios no Pantanal | H24: =IFERROR(INDEX(Aux!$K$6:$K$16,MATCH(1,Aux!$O$6:$O$16,0)),"") -> 3
B25: =IF(C25="","",2) -> 2 | C25: =IFERROR(INDEX(Aux!$I$6:$I$16,MATCH(2,Aux!$M$6:$M$16,0)),"") -> [Agropecuária] OP-02 – Mercados para produtos diferenciados e certificados (carne sustentável/orgânica, origem Pantanal) | D25: =IFERROR(INDEX(Aux!$K$6:$K$16,MATCH(2,Aux!$M$6:$M$16,0)),"") -> 3 | F25: =IF(G25="","",2) -> 2 | G25: =IFERROR(INDEX(Aux!$I$6:$I$16,MATCH(2,Aux!$O$6:$O$16,0)),"") -> [Agropecuária] AM-02 – Volatilidade de preços de commodities (boi gordo, soja, milho) | H25: =IFERROR(INDEX(Aux!$K$6:$K$16,MATCH(2,Aux!$O$6:$O$16,0)),"") -> 3
B26: =IF(C26="","",3) -> 3 | C26: =IFERROR(INDEX(Aux!$I$6:$I$16,MATCH(3,Aux!$M$6:$M$16,0)),"") -> [Comércio e Serviços] OP-03 – Expansão do turismo de natureza, pesca esportiva e ecoturismo | D26: =IFERROR(INDEX(Aux!$K$6:$K$16,MATCH(3,Aux!$M$6:$M$16,0)),"") -> 3 | F26: =IF(G26="","",3) -> 3 | G26: =IFERROR(INDEX(Aux!$I$6:$I$16,MATCH(3,Aux!$O$6:$O$16,0)),"") -> [Agropecuária] AM-03 – Exigências ambientais de mercados importadores e barreiras ligadas a desmatamento (ex.: EUDR) | H26: =IFERROR(INDEX(Aux!$K$6:$K$16,MATCH(3,Aux!$O$6:$O$16,0)),"") -> 3
B27: =IF(C27="","",4) -> 4 | C27: =IFERROR(INDEX(Aux!$I$6:$I$16,MATCH(4,Aux!$M$6:$M$16,0)),"") -> [Indústria] OP-04 – Agroindustrialização e verticalização (frigoríficos, laticínios, sucroenergético) | D27: =IFERROR(INDEX(Aux!$K$6:$K$16,MATCH(4,Aux!$M$6:$M$16,0)),"") -> 2 | F27: =IF(G27="","",4) -> 4 | G27: =IFERROR(INDEX(Aux!$I$6:$I$16,MATCH(4,Aux!$O$6:$O$16,0)),"") -> [Estrutura Econômica e Fiscal] AM-04 – Transição da Reforma Tributária (IBS/CBS) e efeitos sobre a repartição de receitas municipais | H27: =IFERROR(INDEX(Aux!$K$6:$K$16,MATCH(4,Aux!$O$6:$O$16,0)),"") -> 2
B28: =IF(C28="","",5) -> 5 | C28: =IFERROR(INDEX(Aux!$I$6:$I$16,MATCH(5,Aux!$M$6:$M$16,0)),"") -> [Estrutura Econômica e Fiscal] OP-05 – Corredores logísticos (rodovias federais, ferrovia, hidrovia do Paraguai) | D28: =IFERROR(INDEX(Aux!$K$6:$K$16,MATCH(5,Aux!$M$6:$M$16,0)),"") -> 3 | F28: =IF(G28="","",5) | G28: =IFERROR(INDEX(Aux!$I$6:$I$16,MATCH(5,Aux!$O$6:$O$16,0)),"") | H28: =IFERROR(INDEX(Aux!$K$6:$K$16,MATCH(5,Aux!$O$6:$O$16,0)),"")
B29: =IF(C29="","",6) -> 6 | C29: =IFERROR(INDEX(Aux!$I$6:$I$16,MATCH(6,Aux!$M$6:$M$16,0)),"") -> [Estrutura Econômica e Fiscal] OP-06 – Instrumentos de fomento e financiamento (FCO, crédito rural, PSA, mercado de carbono) | D29: =IFERROR(INDEX(Aux!$K$6:$K$16,MATCH(6,Aux!$M$6:$M$16,0)),"") -> 3 | F29: =IF(G29="","",6) | G29: =IFERROR(INDEX(Aux!$I$6:$I$16,MATCH(6,Aux!$O$6:$O$16,0)),"") | H29: =IFERROR(INDEX(Aux!$K$6:$K$16,MATCH(6,Aux!$O$6:$O$16,0)),"")
B30: =IF(C30="","",7) | C30: =IFERROR(INDEX(Aux!$I$6:$I$16,MATCH(7,Aux!$M$6:$M$16,0)),"") | D30: =IFERROR(INDEX(Aux!$K$6:$K$16,MATCH(7,Aux!$M$6:$M$16,0)),"") | F30: =IF(G30="","",7) | G30: =IFERROR(INDEX(Aux!$I$6:$I$16,MATCH(7,Aux!$O$6:$O$16,0)),"") | H30: =IFERROR(INDEX(Aux!$K$6:$K$16,MATCH(7,Aux!$O$6:$O$16,0)),"")
B31: =IF(C31="","",8) | C31: =IFERROR(INDEX(Aux!$I$6:$I$16,MATCH(8,Aux!$M$6:$M$16,0)),"") | D31: =IFERROR(INDEX(Aux!$K$6:$K$16,MATCH(8,Aux!$M$6:$M$16,0)),"") | F31: =IF(G31="","",8) | G31: =IFERROR(INDEX(Aux!$I$6:$I$16,MATCH(8,Aux!$O$6:$O$16,0)),"") | H31: =IFERROR(INDEX(Aux!$K$6:$K$16,MATCH(8,Aux!$O$6:$O$16,0)),"")
B32: =IF(C32="","",9) | C32: =IFERROR(INDEX(Aux!$I$6:$I$16,MATCH(9,Aux!$M$6:$M$16,0)),"") | D32: =IFERROR(INDEX(Aux!$K$6:$K$16,MATCH(9,Aux!$M$6:$M$16,0)),"") | F32: =IF(G32="","",9) | G32: =IFERROR(INDEX(Aux!$I$6:$I$16,MATCH(9,Aux!$O$6:$O$16,0)),"") | H32: =IFERROR(INDEX(Aux!$K$6:$K$16,MATCH(9,Aux!$O$6:$O$16,0)),"")
B33: =IF(C33="","",10) | C33: =IFERROR(INDEX(Aux!$I$6:$I$16,MATCH(10,Aux!$M$6:$M$16,0)),"") | D33: =IFERROR(INDEX(Aux!$K$6:$K$16,MATCH(10,Aux!$M$6:$M$16,0)),"") | F33: =IF(G33="","",10) | G33: =IFERROR(INDEX(Aux!$I$6:$I$16,MATCH(10,Aux!$O$6:$O$16,0)),"") | H33: =IFERROR(INDEX(Aux!$K$6:$K$16,MATCH(10,Aux!$O$6:$O$16,0)),"")
B34: =IF(C34="","",11) | C34: =IFERROR(INDEX(Aux!$I$6:$I$16,MATCH(11,Aux!$M$6:$M$16,0)),"") | D34: =IFERROR(INDEX(Aux!$K$6:$K$16,MATCH(11,Aux!$M$6:$M$16,0)),"") | F34: =IF(G34="","",11) | G34: =IFERROR(INDEX(Aux!$I$6:$I$16,MATCH(11,Aux!$O$6:$O$16,0)),"") | H34: =IFERROR(INDEX(Aux!$K$6:$K$16,MATCH(11,Aux!$O$6:$O$16,0)),"")
B35: =IF(C35="","",12) | C35: =IFERROR(INDEX(Aux!$I$6:$I$16,MATCH(12,Aux!$M$6:$M$16,0)),"") | D35: =IFERROR(INDEX(Aux!$K$6:$K$16,MATCH(12,Aux!$M$6:$M$16,0)),"") | F35: =IF(G35="","",12) | G35: =IFERROR(INDEX(Aux!$I$6:$I$16,MATCH(12,Aux!$O$6:$O$16,0)),"") | H35: =IFERROR(INDEX(Aux!$K$6:$K$16,MATCH(12,Aux!$O$6:$O$16,0)),"")
C36: =IF(SUM(Aux!$L$6:$L$16)>12,"+ "&(SUM(Aux!$L$6:$L$16)-12)&" item(ns) não exibido(s) — ver abas de dados","") | G36: =IF(SUM(Aux!$N$6:$N$16)>12,"+ "&(SUM(Aux!$N$6:$N$16)-12)&" item(ns) não exibido(s) — ver abas de dados","")
B38: Forças/Fraquezas: classificação automática dos indicadores internos segundo os limiares da aba 'Indicadores (F-W)'. Oportunidades/Ameaças: fatores externos com intensidade ≥ corte definido em 'Parâmetros'.

Sheet Painel
A1: PAINEL REGIONAL — SÍNTESE DOS 13 MUNICÍPIOS
A3: Município | B3: Forças | C3: Fraquezas | D3: Neutros | E3: Sem dado | F3: Saldo interno (F − W) | G3: Oportunidades | H3: Ameaças | I3: Saldo externo (O − T)
A4: Barão de Melgaço | B4: =COUNTIF('Indicadores (F-W)'!O$6:O$21,"Força") -> 3 | C4: =COUNTIF('Indicadores (F-W)'!O$6:O$21,"Fraqueza") -> 10 | D4: =COUNTIF('Indicadores (F-W)'!O$6:O$21,"Neutro") -> 1 | E4: =COUNTBLANK('Indicadores (F-W)'!N$6:N$21) -> 2 | F4: =B4-C4 -> -7 | G4: =COUNTIFS('Fatores Externos (O-A)'!$B$6:$B$16,"Oportunidade",'Fatores Externos (O-A)'!F$6:F$16,">="&Parâmetros!$B$5) -> 3 | H4: =COUNTIFS('Fatores Externos (O-A)'!$B$6:$B$16,"Ameaça",'Fatores Externos (O-A)'!F$6:F$16,">="&Parâmetros!$B$5) -> 4 | I4: =G4-H4 -> -1
A5: Cáceres | B5: =COUNTIF('Indicadores (F-W)'!Q$6:Q$21,"Força") -> 3 | C5: =COUNTIF('Indicadores (F-W)'!Q$6:Q$21,"Fraqueza") -> 8 | D5: =COUNTIF('Indicadores (F-W)'!Q$6:Q$21,"Neutro") -> 3 | E5: =COUNTBLANK('Indicadores (F-W)'!P$6:P$21) -> 2 | F5: =B5-C5 -> -5 | G5: =COUNTIFS('Fatores Externos (O-A)'!$B$6:$B$16,"Oportunidade",'Fatores Externos (O-A)'!G$6:G$16,">="&Parâmetros!$B$5) -> 6 | H5: =COUNTIFS('Fatores Externos (O-A)'!$B$6:$B$16,"Ameaça",'Fatores Externos (O-A)'!G$6:G$16,">="&Parâmetros!$B$5) -> 4 | I5: =G5-H5 -> 2
A6: Curvelândia | B6: =COUNTIF('Indicadores (F-W)'!S$6:S$21,"Força") -> 3 | C6: =COUNTIF('Indicadores (F-W)'!S$6:S$21,"Fraqueza") -> 10 | D6: =COUNTIF('Indicadores (F-W)'!S$6:S$21,"Neutro") -> 1 | E6: =COUNTBLANK('Indicadores (F-W)'!R$6:R$21) -> 2 | F6: =B6-C6 -> -7 | G6: =COUNTIFS('Fatores Externos (O-A)'!$B$6:$B$16,"Oportunidade",'Fatores Externos (O-A)'!H$6:H$16,">="&Parâmetros!$B$5) -> 2 | H6: =COUNTIFS('Fatores Externos (O-A)'!$B$6:$B$16,"Ameaça",'Fatores Externos (O-A)'!H$6:H$16,">="&Parâmetros!$B$5) -> 3 | I6: =G6-H6 -> -1
A7: Glória D'Oeste | B7: =COUNTIF('Indicadores (F-W)'!U$6:U$21,"Força") -> 3 | C7: =COUNTIF('Indicadores (F-W)'!U$6:U$21,"Fraqueza") -> 10 | D7: =COUNTIF('Indicadores (F-W)'!U$6:U$21,"Neutro") -> 1 | E7: =COUNTBLANK('Indicadores (F-W)'!T$6:T$21) -> 2 | F7: =B7-C7 -> -7 | G7: =COUNTIFS('Fatores Externos (O-A)'!$B$6:$B$16,"Oportunidade",'Fatores Externos (O-A)'!I$6:I$16,">="&Parâmetros!$B$5) -> 2 | H7: =COUNTIFS('Fatores Externos (O-A)'!$B$6:$B$16,"Ameaça",'Fatores Externos (O-A)'!I$6:I$16,">="&Parâmetros!$B$5) -> 3 | I7: =G7-H7 -> -1
A8: Itiquira | B8: =COUNTIF('Indicadores (F-W)'!W$6:W$21,"Força") -> 7 | C8: =COUNTIF('Indicadores (F-W)'!W$6:W$21,"Fraqueza") -> 6 | D8: =COUNTIF('Indicadores (F-W)'!W$6:W$21,"Neutro") -> 1 | E8: =COUNTBLANK('Indicadores (F-W)'!V$6:V$21) -> 2 | F8: =B8-C8 -> 1 | G8: =COUNTIFS('Fatores Externos (O-A)'!$B$6:$B$16,"Oportunidade",'Fatores Externos (O-A)'!J$6:J$16,">="&Parâmetros!$B$5) -> 5 | H8: =COUNTIFS('Fatores Externos (O-A)'!$B$6:$B$16,"Ameaça",'Fatores Externos (O-A)'!J$6:J$16,">="&Parâmetros!$B$5) -> 5 | I8: =G8-H8 -> 0
A9: Juscimeira | B9: =COUNTIF('Indicadores (F-W)'!Y$6:Y$21,"Força") -> 3 | C9: =COUNTIF('Indicadores (F-W)'!Y$6:Y$21,"Fraqueza") -> 7 | D9: =COUNTIF('Indicadores (F-W)'!Y$6:Y$21,"Neutro") -> 4 | E9: =COUNTBLANK('Indicadores (F-W)'!X$6:X$21) -> 2 | F9: =B9-C9 -> -4 | G9: =COUNTIFS('Fatores Externos (O-A)'!$B$6:$B$16,"Oportunidade",'Fatores Externos (O-A)'!K$6:K$16,">="&Parâmetros!$B$5) -> 5 | H9: =COUNTIFS('Fatores Externos (O-A)'!$B$6:$B$16,"Ameaça",'Fatores Externos (O-A)'!K$6:K$16,">="&Parâmetros!$B$5) -> 4 | I9: =G9-H9 -> 1
A10: Lambari D'Oeste | B10: =COUNTIF('Indicadores (F-W)'!AA$6:AA$21,"Força") -> 2 | C10: =COUNTIF('Indicadores (F-W)'!AA$6:AA$21,"Fraqueza") -> 9 | D10: =COUNTIF('Indicadores (F-W)'!AA$6:AA$21,"Neutro") -> 3 | E10: =COUNTBLANK('Indicadores (F-W)'!Z$6:Z$21) -> 2 | F10: =B10-C10 -> -7 | G10: =COUNTIFS('Fatores Externos (O-A)'!$B$6:$B$16,"Oportunidade",'Fatores Externos (O-A)'!L$6:L$16,">="&Parâmetros!$B$5) -> 3 | H10: =COUNTIFS('Fatores Externos (O-A)'!$B$6:$B$16,"Ameaça",'Fatores Externos (O-A)'!L$6:L$16,">="&Parâmetros!$B$5) -> 4 | I10: =G10-H10 -> -1
A11: Mirassol D'Oeste | B11: =COUNTIF('Indicadores (F-W)'!AC$6:AC$21,"Força") -> 2 | C11: =COUNTIF('Indicadores (F-W)'!AC$6:AC$21,"Fraqueza") -> 8 | D11: =COUNTIF('Indicadores (F-W)'!AC$6:AC$21,"Neutro") -> 4 | E11: =COUNTBLANK('Indicadores (F-W)'!AB$6:AB$21) -> 2 | F11: =B11-C11 -> -6 | G11: =COUNTIFS('Fatores Externos (O-A)'!$B$6:$B$16,"Oportunidade",'Fatores Externos (O-A)'!M$6:M$16,">="&Parâmetros!$B$5) -> 4 | H11: =COUNTIFS('Fatores Externos (O-A)'!$B$6:$B$16,"Ameaça",'Fatores Externos (O-A)'!M$6:M$16,">="&Parâmetros!$B$5) -> 1 | I11: =G11-H11 -> 3
A12: Nossa Senhora do Livramento | B12: =COUNTIF('Indicadores (F-W)'!AE$6:AE$21,"Força") -> 4 | C12: =COUNTIF('Indicadores (F-W)'!AE$6:AE$21,"Fraqueza") -> 8 | D12: =COUNTIF('Indicadores (F-W)'!AE$6:AE$21,"Neutro") -> 2 | E12: =COUNTBLANK('Indicadores (F-W)'!AD$6:AD$21) -> 2 | F12: =B12-C12 -> -4 | G12: =COUNTIFS('Fatores Externos (O-A)'!$B$6:$B$16,"Oportunidade",'Fatores Externos (O-A)'!N$6:N$16,">="&Parâmetros!$B$5) -> 4 | H12: =COUNTIFS('Fatores Externos (O-A)'!$B$6:$B$16,"Ameaça",'Fatores Externos (O-A)'!N$6:N$16,">="&Parâmetros!$B$5) -> 3 | I12: =G12-H12 -> 1
A13: Poconé | B13: =COUNTIF('Indicadores (F-W)'!AG$6:AG$21,"Força") -> 1 | C13: =COUNTIF('Indicadores (F-W)'!AG$6:AG$21,"Fraqueza") -> 11 | D13: =COUNTIF('Indicadores (F-W)'!AG$6:AG$21,"Neutro") -> 2 | E13: =COUNTBLANK('Indicadores (F-W)'!AF$6:AF$21) -> 2 | F13: =B13-C13 -> -10 | G13: =COUNTIFS('Fatores Externos (O-A)'!$B$6:$B$16,"Oportunidade",'Fatores Externos (O-A)'!O$6:O$16,">="&Parâmetros!$B$5) -> 4 | H13: =COUNTIFS('Fatores Externos (O-A)'!$B$6:$B$16,"Ameaça",'Fatores Externos (O-A)'!O$6:O$16,">="&Parâmetros!$B$5) -> 4 | I13: =G13-H13 -> 0
A14: Porto Esperidião | B14: =COUNTIF('Indicadores (F-W)'!AI$6:AI$21,"Força") -> 3 | C14: =COUNTIF('Indicadores (F-W)'!AI$6:AI$21,"Fraqueza") -> 9 | D14: =COUNTIF('Indicadores (F-W)'!AI$6:AI$21,"Neutro") -> 2 | E14: =COUNTBLANK('Indicadores (F-W)'!AH$6:AH$21) -> 2 | F14: =B14-C14 -> -6 | G14: =COUNTIFS('Fatores Externos (O-A)'!$B$6:$B$16,"Oportunidade",'Fatores Externos (O-A)'!P$6:P$16,">="&Parâmetros!$B$5) -> 3 | H14: =COUNTIFS('Fatores Externos (O-A)'!$B$6:$B$16,"Ameaça",'Fatores Externos (O-A)'!P$6:P$16,">="&Parâmetros!$B$5) -> 4 | I14: =G14-H14 -> -1
A15: Rondonópolis | B15: =COUNTIF('Indicadores (F-W)'!AK$6:AK$21,"Força") -> 4 | C15: =COUNTIF('Indicadores (F-W)'!AK$6:AK$21,"Fraqueza") -> 3 | D15: =COUNTIF('Indicadores (F-W)'!AK$6:AK$21,"Neutro") -> 7 | E15: =COUNTBLANK('Indicadores (F-W)'!AJ$6:AJ$21) -> 2 | F15: =B15-C15 -> 1 | G15: =COUNTIFS('Fatores Externos (O-A)'!$B$6:$B$16,"Oportunidade",'Fatores Externos (O-A)'!Q$6:Q$16,">="&Parâmetros!$B$5) -> 5 | H15: =COUNTIFS('Fatores Externos (O-A)'!$B$6:$B$16,"Ameaça",'Fatores Externos (O-A)'!Q$6:Q$16,">="&Parâmetros!$B$5) -> 3 | I15: =G15-H15 -> 2
A16: Santo Antônio do Leverger | B16: =COUNTIF('Indicadores (F-W)'!AM$6:AM$21,"Força") -> 2 | C16: =COUNTIF('Indicadores (F-W)'!AM$6:AM$21,"Fraqueza") -> 11 | D16: =COUNTIF('Indicadores (F-W)'!AM$6:AM$21,"Neutro") -> 1 | E16: =COUNTBLANK('Indicadores (F-W)'!AL$6:AL$21) -> 2 | F16: =B16-C16 -> -9 | G16: =COUNTIFS('Fatores Externos (O-A)'!$B$6:$B$16,"Oportunidade",'Fatores Externos (O-A)'!R$6:R$16,">="&Parâmetros!$B$5) -> 5 | H16: =COUNTIFS('Fatores Externos (O-A)'!$B$6:$B$16,"Ameaça",'Fatores Externos (O-A)'!R$6:R$16,">="&Parâmetros!$B$5) -> 5 | I16: =G16-H16 -> 0
A19: Frequência regional dos indicadores internos (nº de municípios)
A20: Cód. | B20: Indicador | C20: Força | D20: Neutro | E20: Fraqueza | F20: Sem dado | G20: Leitura regional
A21: ='Indicadores (F-W)'!A6 -> AGR-01 | B21: ='Indicadores (F-W)'!C6 -> Quociente locacional do VAB agropecuário (base MT) | C21: =COUNTIF('Indicadores (F-W)'!$N6:$AM6,"Força") -> 6 | D21: =COUNTIF('Indicadores (F-W)'!$N6:$AM6,"Neutro") -> 2 | E21: =COUNTIF('Indicadores (F-W)'!$N6:$AM6,"Fraqueza") -> 5 | F21: =13-C21-D21-E21 -> 0 | G21: =IF(C21+D21+E21=0,"sem dados",IF(C21>=13/2,"Força regional",IF(E21>=13/2,"Fraqueza regional","Heterogêneo"))) -> Heterogêneo
A22: ='Indicadores (F-W)'!A7 -> AGR-02 | B22: ='Indicadores (F-W)'!C7 -> Valor da produção das lavouras por área colhida | C22: =COUNTIF('Indicadores (F-W)'!$N7:$AM7,"Força") -> 6 | D22: =COUNTIF('Indicadores (F-W)'!$N7:$AM7,"Neutro") -> 6 | E22: =COUNTIF('Indicadores (F-W)'!$N7:$AM7,"Fraqueza") -> 1 | F22: =13-C22-D22-E22 -> 0 | G22: =IF(C22+D22+E22=0,"sem dados",IF(C22>=13/2,"Força regional",IF(E22>=13/2,"Fraqueza regional","Heterogêneo"))) -> Heterogêneo
A23: ='Indicadores (F-W)'!A8 -> AGR-03 | B23: ='Indicadores (F-W)'!C8 -> Variação do efetivo bovino em 5 anos | C23: =COUNTIF('Indicadores (F-W)'!$N8:$AM8,"Força") -> 6 | D23: =COUNTIF('Indicadores (F-W)'!$N8:$AM8,"Neutro") -> 4 | E23: =COUNTIF('Indicadores (F-W)'!$N8:$AM8,"Fraqueza") -> 3 | F23: =13-C23-D23-E23 -> 0 | G23: =IF(C23+D23+E23=0,"sem dados",IF(C23>=13/2,"Força regional",IF(E23>=13/2,"Fraqueza regional","Heterogêneo"))) -> Heterogêneo
A24: ='Indicadores (F-W)'!A9 -> AGR-04 | B24: ='Indicadores (F-W)'!C9 -> Estabelecimentos agropecuários que receberam assistência técnica | C24: =COUNTIF('Indicadores (F-W)'!$N9:$AM9,"Força") -> 0 | D24: =COUNTIF('Indicadores (F-W)'!$N9:$AM9,"Neutro") -> 0 | E24: =COUNTIF('Indicadores (F-W)'!$N9:$AM9,"Fraqueza") -> 0 | F24: =13-C24-D24-E24 -> 13 | G24: =IF(C24+D24+E24=0,"sem dados",IF(C24>=13/2,"Força regional",IF(E24>=13/2,"Fraqueza regional","Heterogêneo"))) -> sem dados
A25: ='Indicadores (F-W)'!A10 -> AGR-05 | B25: ='Indicadores (F-W)'!C10 -> Diversificação agrícola (1 − HHI do valor da produção das lavouras) | C25: =COUNTIF('Indicadores (F-W)'!$N10:$AM10,"Força") -> 0 | D25: =COUNTIF('Indicadores (F-W)'!$N10:$AM10,"Neutro") -> 0 | E25: =COUNTIF('Indicadores (F-W)'!$N10:$AM10,"Fraqueza") -> 0 | F25: =13-C25-D25-E25 -> 13 | G25: =IF(C25+D25+E25=0,"sem dados",IF(C25>=13/2,"Força regional",IF(E25>=13/2,"Fraqueza regional","Heterogêneo"))) -> sem dados
A26: ='Indicadores (F-W)'!A11 -> IND-01 | B26: ='Indicadores (F-W)'!C11 -> Quociente locacional do VAB industrial (base MT) | C26: =COUNTIF('Indicadores (F-W)'!$N11:$AM11,"Força") -> 4 | D26: =COUNTIF('Indicadores (F-W)'!$N11:$AM11,"Neutro") -> 3 | E26: =COUNTIF('Indicadores (F-W)'!$N11:$AM11,"Fraqueza") -> 6 | F26: =13-C26-D26-E26 -> 0 | G26: =IF(C26+D26+E26=0,"sem dados",IF(C26>=13/2,"Força regional",IF(E26>=13/2,"Fraqueza regional","Heterogêneo"))) -> Heterogêneo
A27: ='Indicadores (F-W)'!A12 -> IND-02 | B27: ='Indicadores (F-W)'!C12 -> Variação do emprego formal na indústria em 5 anos | C27: =COUNTIF('Indicadores (F-W)'!$N12:$AM12,"Força") -> 8 | D27: =COUNTIF('Indicadores (F-W)'!$N12:$AM12,"Neutro") -> 0 | E27: =COUNTIF('Indicadores (F-W)'!$N12:$AM12,"Fraqueza") -> 5 | F27: =13-C27-D27-E27 -> 0 | G27: =IF(C27+D27+E27=0,"sem dados",IF(C27>=13/2,"Força regional",IF(E27>=13/2,"Fraqueza regional","Heterogêneo"))) -> Força regional
A28: ='Indicadores (F-W)'!A13 -> IND-03 | B28: ='Indicadores (F-W)'!C13 -> Remuneração média do emprego formal industrial | C28: =COUNTIF('Indicadores (F-W)'!$N13:$AM13,"Força") -> 0 | D28: =COUNTIF('Indicadores (F-W)'!$N13:$AM13,"Neutro") -> 5 | E28: =COUNTIF('Indicadores (F-W)'!$N13:$AM13,"Fraqueza") -> 8 | F28: =13-C28-D28-E28 -> 0 | G28: =IF(C28+D28+E28=0,"sem dados",IF(C28>=13/2,"Força regional",IF(E28>=13/2,"Fraqueza regional","Heterogêneo"))) -> Fraqueza regional
A29: ='Indicadores (F-W)'!A14 -> CS-01 | B29: ='Indicadores (F-W)'!C14 -> Quociente locacional do VAB de serviços, exceto adm. pública (base MT) | C29: =COUNTIF('Indicadores (F-W)'!$N14:$AM14,"Força") -> 2 | D29: =COUNTIF('Indicadores (F-W)'!$N14:$AM14,"Neutro") -> 2 | E29: =COUNTIF('Indicadores (F-W)'!$N14:$AM14,"Fraqueza") -> 9 | F29: =13-C29-D29-E29 -> 0 | G29: =IF(C29+D29+E29=0,"sem dados",IF(C29>=13/2,"Força regional",IF(E29>=13/2,"Fraqueza regional","Heterogêneo"))) -> Fraqueza regional
A30: ='Indicadores (F-W)'!A15 -> CS-02 | B30: ='Indicadores (F-W)'!C15 -> Variação do emprego formal em comércio e serviços em 5 anos | C30: =COUNTIF('Indicadores (F-W)'!$N15:$AM15,"Força") -> 3 | D30: =COUNTIF('Indicadores (F-W)'!$N15:$AM15,"Neutro") -> 1 | E30: =COUNTIF('Indicadores (F-W)'!$N15:$AM15,"Fraqueza") -> 9 | F30: =13-C30-D30-E30 -> 0 | G30: =IF(C30+D30+E30=0,"sem dados",IF(C30>=13/2,"Força regional",IF(E30>=13/2,"Fraqueza regional","Heterogêneo"))) -> Fraqueza regional
A31: ='Indicadores (F-W)'!A16 -> CS-03 | B31: ='Indicadores (F-W)'!C16 -> Empresas e outras organizações ativas por mil habitantes | C31: =COUNTIF('Indicadores (F-W)'!$N16:$AM16,"Força") -> 1 | D31: =COUNTIF('Indicadores (F-W)'!$N16:$AM16,"Neutro") -> 1 | E31: =COUNTIF('Indicadores (F-W)'!$N16:$AM16,"Fraqueza") -> 11 | F31: =13-C31-D31-E31 -> 0 | G31: =IF(C31+D31+E31=0,"sem dados",IF(C31>=13/2,"Força regional",IF(E31>=13/2,"Fraqueza regional","Heterogêneo"))) -> Fraqueza regional
A32: ='Indicadores (F-W)'!A17 -> EST-01 | B32: ='Indicadores (F-W)'!C17 -> PIB per capita | C32: =COUNTIF('Indicadores (F-W)'!$N17:$AM17,"Força") -> 1 | D32: =COUNTIF('Indicadores (F-W)'!$N17:$AM17,"Neutro") -> 1 | E32: =COUNTIF('Indicadores (F-W)'!$N17:$AM17,"Fraqueza") -> 11 | F32: =13-C32-D32-E32 -> 0 | G32: =IF(C32+D32+E32=0,"sem dados",IF(C32>=13/2,"Força regional",IF(E32>=13/2,"Fraqueza regional","Heterogêneo"))) -> Fraqueza regional
... A36: ='Indicadores (F-W)'!A21 -> EST-05 | B36: ='Indicadores (F-W)'!C21 -> Receitas próprias / receita corrente | C36: =COUNTIF('Indicadores (F-W)'!$N21:$AM21,"Força") -> 1 | D36: =COUNTIF('Indicadores (F-W)'!$N21:$AM21,"Neutro") -> 1 | E36: =COUNTIF('Indicadores (F-W)'!$N21:$AM21,"Fraqueza") -> 11 | F36: =13-C36-D36-E36 -> 0 | G36: =IF(C36+D36+E36=0,"sem dados",IF(C36>=13/2,"Força regional",IF(E36>=13/2,"Fraqueza regional","Heterogêneo"))) -> Fraqueza regional
A38: Frequência regional dos fatores externos (nº de municípios com intensidade ≥ corte)
A39: Cód. | B39: Fator externo | C39: Tipo | D39: Nº municípios | E39: Intensidade média
A40: ='Fatores Externos (O-A)'!A6 -> OP-01 | B40: ='Fatores Externos (O-A)'!D6 -> Demanda externa por carne bovina e proteína animal | C40: ='Fatores Externos (O-A)'!B6 -> Oportunidade | D40: =COUNTIF('Fatores Externos (O-A)'!$F6:$R6,">="&Parâmetros!$B$5) -> 12 | E40: =IF(COUNT('Fatores Externos (O-A)'!$F6:$R6)=0,"",AVERAGE('Fatores Externos (O-A)'!$F6:$R6)) -> 2.1538462
A41: ='Fatores Externos (O-A)'!A7 -> OP-02 | B41: ='Fatores Externos (O-A)'!D7 -> Mercados para produtos diferenciados e certificados (carne sustentável/orgânica, origem Pantanal) | C41: ='Fatores Externos (O-A)'!B7 -> Oportunidade | D41: =COUNTIF('Fatores Externos (O-A)'!$F7:$R7,">="&Parâmetros!$B$5) -> 6 | E41: =IF(COUNT('Fatores Externos (O-A)'!$F7:$R7)=0,"",AVERAGE('Fatores Externos (O-A)'!$F7:$R7)) -> 1.7692308
A42: ='Fatores Externos (O-A)'!A8 -> OP-03 | B42: ='Fatores Externos (O-A)'!D8 -> Expansão do turismo de natureza, pesca esportiva e ecoturismo | C42: ='Fatores Externos (O-A)'!B8 -> Oportunidade | D42: =COUNTIF('Fatores Externos (O-A)'!$F8:$R8,">="&Parâmetros!$B$5) -> 6 | E42: =IF(COUNT('Fatores Externos (O-A)'!$F8:$R8)=0,"",AVERAGE('Fatores Externos (O-A)'!$F8:$R8)) -> 1.6153846
A43: ='Fatores Externos (O-A)'!A9 -> OP-04 | B43: ='Fatores Externos (O-A)'!D9 -> Agroindustrialização e verticalização (frigoríficos, laticínios, sucroenergético) | C43: ='Fatores Externos (O-A)'!B9 -> Oportunidade | D43: =COUNTIF('Fatores Externos (O-A)'!$F9:$R9,">="&Parâmetros!$B$5) -> 6 | E43: =IF(COUNT('Fatores Externos (O-A)'!$F9:$R9)=0,"",AVERAGE('Fatores Externos (O-A)'!$F9:$R9)) -> 1.6153846
A44: ='Fatores Externos (O-A)'!A10 -> OP-05 | B44: ='Fatores Externos (O-A)'!D10 -> Corredores logísticos (rodovias federais, ferrovia, hidrovia do Paraguai) | C44: ='Fatores Externos (O-A)'!B10 -> Oportunidade | D44: =COUNTIF('Fatores Externos (O-A)'!$F10:$R10,">="&Parâmetros!$B$5) -> 8 | E44: =IF(COUNT('Fatores Externos (O-A)'!$F10:$R10)=0,"",AVERAGE('Fatores Externos (O-A)'!$F10:$R10)) -> 1.7692308
A45: ='Fatores Externos (O-A)'!A11 -> OP-06 | B45: ='Fatores Externos (O-A)'!D11 -> Instrumentos de fomento e financiamento (FCO, crédito rural, PSA, mercado de carbono) | C45: ='Fatores Externos (O-A)'!B11 -> Oportunidade | D45: =COUNTIF('Fatores Externos (O-A)'!$F11:$R11,">="&Parâmetros!$B$5) -> 13 | E45: =IF(COUNT('Fatores Externos (O-A)'!$F11:$R11)=0,"",AVERAGE('Fatores Externos (O-A)'!$F11:$R11)) -> 2.3076923
A46: ='Fatores Externos (O-A)'!A12 -> AM-01 | B46: ='Fatores Externos (O-A)'!D12 -> Eventos climáticos extremos: secas prolongadas e incêndios no Pantanal | C46: ='Fatores Externos (O-A)'!B12 -> Ameaça | D46: =COUNTIF('Fatores Externos (O-A)'!$F12:$R12,">="&Parâmetros!$B$5) -> 7 | E46: =IF(COUNT('Fatores Externos (O-A)'!$F12:$R12)=0,"",AVERAGE('Fatores Externos (O-A)'!$F12:$R12)) -> 1.8461538
A47: ='Fatores Externos (O-A)'!A13 -> AM-02 | B47: ='Fatores Externos (O-A)'!D13 -> Volatilidade de preços de commodities (boi gordo, soja, milho) | C47: ='Fatores Externos (O-A)'!B13 -> Ameaça | D47: =COUNTIF('Fatores Externos (O-A)'!$F13:$R13,">="&Parâmetros!$B$5) -> 12 | E47: =IF(COUNT('Fatores Externos (O-A)'!$F13:$R13)=0,"",AVERAGE('Fatores Externos (O-A)'!$F13:$R13)) -> 2.2307692
...

Sheet Ranking Locacional
A1: RANKING LOCACIONAL — ESPECIALIZAÇÃO E DIVERSIFICAÇÃO PRODUTIVA (VAB 2021, base MT)
A2: Calculado a partir dos QLs e da participação da administração pública na aba 'Indicadores (F-W)'. Atualiza automaticamente quando esses dados mudarem.
A4: Participação setorial de MT no VAB total (2021)
A5: Agropecuária | B5: 0.379769 | C5: Fonte: IBGE, SIDRA Tabela 5938 — soma dos 141 municípios de MT (ver 'Fontes e Notas').
A6: Indústria | B6: 0.152977
A7: Serviços (exceto adm. pública) | B7: 0.348365
A8: Administração pública | B8: 0.118888
E10: Participação no VAB municipal
A11: Município | B11: QL agropecuária | C11: QL indústria | D11: QL serviços | E11: Agropecuária | F11: Indústria | G11: Serviços | H11: Adm. pública | I11: Soma (conferência) | J11: Coef. de especialização (0–1) | K11: Posição especialização | L11: HHI setorial | M11: Índice de diversificação (0–1) | N11: Posição diversificação | O11: Setor dominante | P11: Part. do setor dominante | Q11: Posição QL agro | R11: Posição QL indústria | S11: Posição QL serviços
A12: Barão de Melgaço | B12: ='Indicadores (F-W)'!N6 -> 0.9631 | C12: ='Indicadores (F-W)'!N11 -> 0.169 | D12: ='Indicadores (F-W)'!N14 -> 0.4274 | E12: =B12*$B$5 -> 0.36575552 | F12: =C12*$B$6 -> 0.025853113 | G12: =D12*$B$7 -> 0.1488912 | H12: ='Indicadores (F-W)'!N18/100 -> 0.4595 | I12: =SUM(E12:H12) -> 0.99999984 | J12: =0.5*(ABS(E12-$B$5)+ABS(F12-$B$6)+ABS(G12-$B$7)+ABS(H12-$B$8)) -> 0.34061158 | K12: =RANK(J12,$J$12:$J$24,0) -> 2 | L12: =SUMSQ(E12:H12) -> 0.36775433 | M12: =1-(L12-0.25)/0.75 -> 0.84299423 | N12: =RANK(M12,$M$12:$M$24,0) -> 9 | O12: =INDEX($E$11:$H$11,MATCH(MAX(E12:H12),E12:H12,0)) -> Adm. pública | P12: =MAX(E12:H12) -> 0.4595 | Q12: =RANK(B12,$B$12:$B$24,0) -> 8 | R12: =RANK(C12,$C$12:$C$24,0) -> 13 | S12: =RANK(D12,$D$12:$D$24,0) -> 10 | V12: =B12-ROW()*0.000000001 -> 0.96309999 | W12: =C12-ROW()*0.000000001 -> 0.16899999 | X12: =D12-ROW()*0.000000001 -> 0.42739999 | Y12: =J12-ROW()*0.000000001 -> 0.34061157 | Z12: =M12-ROW()*0.000000001 -> 0.84299422
A13: Cáceres | B13: ='Indicadores (F-W)'!P6 -> 0.3713 | C13: ='Indicadores (F-W)'!P11 -> 0.6374 | D13: ='Indicadores (F-W)'!P14 -> 1.3013 | E13: =B13*$B$5 -> 0.14100823 | F13: =C13*$B$6 -> 0.09750754 | G13: =D13*$B$7 -> 0.45332737 | H13: ='Indicadores (F-W)'!P18/100 -> 0.3082 | I13: =SUM(E13:H13) -> 1.0000431 | J13: =0.5*(ABS(E13-$B$5)+ABS(F13-$B$6)+ABS(G13-$B$7)+ABS(H13-$B$8)) -> 0.2942523 | K13: =RANK(J13,$J$12:$J$24,0) -> 5 | L13: =SUMSQ(E13:H13) -> 0.32988399 | M13: =1-(L13-0.25)/0.75 -> 0.89348801 | N13: =RANK(M13,$M$12:$M$24,0) -> 5 | O13: =INDEX($E$11:$H$11,MATCH(MAX(E13:H13),E13:H13,0)) -> Serviços | P13: =MAX(E13:H13) -> 0.45332737 | Q13: =RANK(B13,$B$12:$B$24,0) -> 12 | R13: =RANK(C13,$C$12:$C$24,0) -> 8 | S13: =RANK(D13,$D$12:$D$24,0) -> 2 | V13: =B13-ROW()*0.000000001 -> 0.37129999 | W13: =C13-ROW()*0.000000001 -> 0.63739999 | X13: =D13-ROW()*0.000000001 -> 1.3013 | Y13: =J13-ROW()*0.000000001 -> 0.29425229 | Z13: =M13-ROW()*0.000000001 -> 0.893488
A14: Curvelândia | B14: ='Indicadores (F-W)'!R6 -> 1.2022 | C14: ='Indicadores (F-W)'!R11 -> 0.4717 | D14: ='Indicadores (F-W)'!R14 -> 0.5029 | E14: =B14*$B$5 -> 0.45655829 | F14: =C14*$B$6 -> 0.072159251 | G14: =D14*$B$7 -> 0.17519276 | H14: ='Indicadores (F-W)'!R18/100 -> 0.2961 | I14: =SUM(E14:H14) -> 1.0000103 | J14: =0.5*(ABS(E14-$B$5)+ABS(F14-$B$6)+ABS(G14-$B$7)+ABS(H14-$B$8)) -> 0.25399564 | K14: =RANK(J14,$J$12:$J$24,0) -> 8 | L14: =SUMSQ(E14:H14) -> 0.33202014 | M14: =1-(L14-0.25)/0.75 -> 0.89063981 | N14: =RANK(M14,$M$12:$M$24,0) -> 6 | O14: =INDEX($E$11:$H$11,MATCH(MAX(E14:H14),E14:H14,0)) -> Agropecuária | P14: =MAX(E14:H14) -> 0.45655829 | Q14: =RANK(B14,$B$12:$B$24,0) -> 6 | R14: =RANK(C14,$C$12:$C$24,0) -> 11 | S14: =RANK(D14,$D$12:$D$24,0) -> 7 | V14: =B14-ROW()*0.000000001 -> 1.2022 | W14: =C14-ROW()*0.000000001 -> 0.47169999 | X14: =D14-ROW()*0.000000001 -> 0.50289999 | Y14: =J14-ROW()*0.000000001 -> 0.25399563 | Z14: =M14-ROW()*0.000000001 -> 0.89063979
A15: Glória D'Oeste | B15: ='Indicadores (F-W)'!T6 -> 1.3866 | C15: ='Indicadores (F-W)'!T11 -> 0.2854 | D15: ='Indicadores (F-W)'!T14 -> 0.4636 | E15: =B15*$B$5 -> 0.5265877 | F15: =C15*$B$6 -> 0.043659636 | G15: =D15*$B$7 -> 0.16150201 | H15: ='Indicadores (F-W)'!T18/100 -> 0.2683 | I15: =SUM(E15:H15) -> 1.0000493 | J15: =0.5*(ABS(E15-$B$5)+ABS(F15-$B$6)+ABS(G15-$B$7)+ABS(H15-$B$8)) -> 0.29620552 | K15: =RANK(J15,$J$12:$J$24,0) -> 4 | L15: =SUMSQ(E15:H15) -> 0.37726856 | M15: =1-(L15-0.25)/0.75 -> 0.83030859 | N15: =RANK(M15,$M$12:$M$24,0) -> 10 | O15: =INDEX($E$11:$H$11,MATCH(MAX(E15:H15),E15:H15,0)) -> Agropecuária | P15: =MAX(E15:H15) -> 0.5265877 | Q15: =RANK(B15,$B$12:$B$24,0) -> 3 | R15: =RANK(C15,$C$12:$C$24,0) -> 12 | S15: =RANK(D15,$D$12:$D$24,0) -> 8 | V15: =B15-ROW()*0.000000001 -> 1.3866 | W15: =C15-ROW()*0.000000001 -> 0.28539999 | X15: =D15-ROW()*0.000000001 -> 0.46359998 | Y15: =J15-ROW()*0.000000001 -> 0.29620551 | Z15: =M15-ROW()*0.000000001 -> 0.83030858
A16: Itiquira | B16: ='Indicadores (F-W)'!V6 -> 1.6266 | C16: ='Indicadores (F-W)'!V11 -> 1.2891 | D16: ='Indicadores (F-W)'!V14 -> 0.3623 | E16: =B16*$B$5 -> 0.61773226 | F16: =C16*$B$6 -> 0.19720265 | G16: =D16*$B$7 -> 0.12621264 | H16: ='Indicadores (F-W)'!V18/100 -> 0.0588 | I16: =SUM(E16:H16) -> 0.99994755 | J16: =0.5*(ABS(E16-$B$5)+ABS(F16-$B$6)+ABS(G16-$B$7)+ABS(H16-$B$8)) -> 0.28221463 | K16: =RANK(J16,$J$12:$J$24,0) -> 7 | L16: =SUMSQ(E16:H16) -> 0.4398691 | M16: =1-(L16-0.25)/0.75 -> 0.74684121 | N16: =RANK(M16,$M$12:$M$24,0) -> 12 | O16: =INDEX($E$11:$H$11,MATCH(MAX(E16:H16),E16:H16,0)) -> Agropecuária | P16: =MAX(E16:H16) -> 0.61773226 | Q16: =RANK(B16,$B$12:$B$24,0) -> 2 | R16: =RANK(C16,$C$12:$C$24,0) -> 3 | S16: =RANK(D16,$D$12:$D$24,0) -> 11 | V16: =B16-ROW()*0.000000001 -> 1.6266 | W16: =C16-ROW()*0.000000001 -> 1.2891 | X16: =D16-ROW()*0.000000001 -> 0.36229998 | Y16: =J16-ROW()*0.000000001 -> 0.28221462 | Z16: =M16-ROW()*0.000000001 -> 0.74684119
A17: Juscimeira | B17: ='Indicadores (F-W)'!X6 -> 1.319 | C17: ='Indicadores (F-W)'!X11 -> 1.1671 | D17: ='Indicadores (F-W)'!X14 -> 0.4388 | E17: =B17*$B$5 -> 0.50091531 | F17: =C17*$B$6 -> 0.17853946 | G17: =D17*$B$7 -> 0.15286256 | H17: ='Indicadores (F-W)'!X18/100 -> 0.1677 | I17: =SUM(E17:H17) -> 1.0000173 | J17: =0.5*(ABS(E17-$B$5)+ABS(F17-$B$6)+ABS(G17-$B$7)+ABS(H17-$B$8)) -> 0.1955116 | K17: =RANK(J17,$J$12:$J$24,0) -> 12 | L17: =SUMSQ(E17:H17) -> 0.33428274 | M17: =1-(L17-0.25)/0.75 -> 0.88762301 | N17: =RANK(M17,$M$12:$M$24,0) -> 7 | O17: =INDEX($E$11:$H$11,MATCH(MAX(E17:H17),E17:H17,0)) -> Agropecuária | P17: =MAX(E17:H17) -> 0.50091531 | Q17: =RANK(B17,$B$12:$B$24,0) -> 5 | R17: =RANK(C17,$C$12:$C$24,0) -> 6 | S17: =RANK(D17,$D$12:$D$24,0) -> 9 | V17: =B17-ROW()*0.000000001 -> 1.319 | W17: =C17-ROW()*0.000000001 -> 1.1671 | X17: =D17-ROW()*0.000000001 -> 0.43879998 | Y17: =J17-ROW()*0.000000001 -> 0.19551159 | Z17: =M17-ROW()*0.000000001 -> 0.887623
A18: Lambari D'Oeste | B18: ='Indicadores (F-W)'!Z6 -> 1.364 | C18: ='Indicadores (F-W)'!Z11 -> 1.1956 | D18: ='Indicadores (F-W)'!Z14 -> 0.3227 | E18: =B18*$B$5 -> 0.51800492 | F18: =C18*$B$6 -> 0.1828993 | G18: =D18*$B$7 -> 0.11241739 | H18: ='Indicadores (F-W)'!Z18/100 -> 0.1867 | I18: =SUM(E18:H18) -> 1.0000216 | J18: =0.5*(ABS(E18-$B$5)+ABS(F18-$B$6)+ABS(G18-$B$7)+ABS(H18-$B$8)) -> 0.23595892 | K18: =RANK(J18,$J$12:$J$24,0) -> 10 | L18: =SUMSQ(E18:H18) -> 0.34927581 | M18: =1-(L18-0.25)/0.75 -> 0.86763226 | N18: =RANK(M18,$M$12:$M$24,0) -> 8 | O18: =INDEX($E$11:$H$11,MATCH(MAX(E18:H18),E18:H18,0)) -> Agropecuária | P18: =MAX(E18:H18) -> 0.51800492 | Q18: =RANK(B18,$B$12:$B$24,0) -> 4 | R18: =RANK(C18,$C$12:$C$24,0) -> 5 | S18: =RANK(D18,$D$12:$D$24,0) -> 13 | V18: =B18-ROW()*0.000000001 -> 1.364 | W18: =C18-ROW()*0.000000001 -> 1.1956 | X18: =D18-ROW()*0.000000001 -> 0.32269998 | Y18: =J18-ROW()*0.000000001 -> 0.2359589 | Z18: =M18-ROW()*0.000000001 -> 0.86763224
A19: Mirassol D'Oeste | B19: ='Indicadores (F-W)'!AB6 -> 0.416 | C19: ='Indicadores (F-W)'!AB11 -> 1.2112 | D19: ='Indicadores (F-W)'!AB14 -> 1.1498 | E19: =B19*$B$5 -> 0.1579839 | F19: =C19*$B$6 -> 0.18528574 | G19: =D19*$B$7 -> 0.40055008 | H19: ='Indicadores (F-W)'!AB18/100 -> 0.2562 | I19: =SUM(E19:H19) -> 1.0000197 | J19: =0.5*(ABS(E19-$B$5)+ABS(F19-$B$6)+ABS(G19-$B$7)+ABS(H19-$B$8)) -> 0.22179546 | K19: =RANK(J19,$J$12:$J$24,0) -> 11 | L19: =SUMSQ(E19:H19) -> 0.28536852 | M19: =1-(L19-0.25)/0.75 -> 0.95284197 | N19: =RANK(M19,$M$12:$M$24,0) -> 3 | O19: =INDEX($E$11:$H$11,MATCH(MAX(E19:H19),E19:H19,0)) -> Serviços | P19: =MAX(E19:H19) -> 0.40055008 | Q19: =RANK(B19,$B$12:$B$24,0) -> 11 | R19: =RANK(C19,$C$12:$C$24,0) -> 4 | S19: =RANK(D19,$D$12:$D$24,0) -> 3 | V19: =B19-ROW()*0.000000001 -> 0.41599998 | W19: =C19-ROW()*0.000000001 -> 1.2112 | X19: =D19-ROW()*0.000000001 -> 1.1498 | Y19: =J19-ROW()*0.000000001 -> 0.22179544 | Z19: =M19-ROW()*0.000000001 -> 0.95284195
A20: Nossa Senhora do Livramento | B20: ='Indicadores (F-W)'!AD6 -> 0.5183 | C20: ='Indicadores (F-W)'!AD11 -> 2.0033 | D20: ='Indicadores (F-W)'!AD14 -> 0.7089 | E20: =B20*$B$5 -> 0.19683427 | F20: =C20*$B$6 -> 0.30645882 | G20: =D20*$B$7 -> 0.24695595 | H20: ='Indicadores (F-W)'!AD18/100 -> 0.2497 | I20: =SUM(E20:H20) -> 0.99994905 | J20: =0.5*(ABS(E20-$B$5)+ABS(F20-$B$6)+ABS(G20-$B$7)+ABS(H20-$B$8)) -> 0.2843188 | K20: =RANK(J20,$J$12:$J$24,0) -> 6 | L20: =SUMSQ(E20:H20) -> 0.25599807 | M20: =1-(L20-0.25)/0.75 -> 0.99200257 | N20: =RANK(M20,$M$12:$M$24,0) -> 1 | O20: =INDEX($E$11:$H$11,MATCH(MAX(E20:H20),E20:H20,0)) -> Indústria | P20: =MAX(E20:H20) -> 0.30645882 | Q20: =RANK(B20,$B$12:$B$24,0) -> 9 | R20: =RANK(C20,$C$12:$C$24,0) -> 1 | S20: =RANK(D20,$D$12:$D$24,0) -> 5 | V20: =B20-ROW()*0.000000001 -> 0.51829998 | W20: =C20-ROW()*0.000000001 -> 2.0033 | X20: =D20-ROW()*0.000000001 -> 0.70889998 | Y20: =J20-ROW()*0.000000001 -> 0.28431878 | Z20: =M20-ROW()*0.000000001 -> 0.99200255
A21: Poconé | B21: ='Indicadores (F-W)'!AF6 -> 0.5066 | C21: ='Indicadores (F-W)'!AF11 -> 0.5947 | D21: ='Indicadores (F-W)'!AF14 -> 1.1034 | E21: =B21*$B$5 -> 0.19239098 | F21: =C21*$B$6 -> 0.090975422 | G21: =D21*$B$7 -> 0.38438594 | H21: ='Indicadores (F-W)'!AF18/100 -> 0.3323 | I21: =SUM(E21:H21) -> 1.0000523 | J21: =0.5*(ABS(E21-$B$5)+ABS(F21-$B$6)+ABS(G21-$B$7)+ABS(H21-$B$8)) -> 0.24940627 | K21: =RANK(J21,$J$12:$J$24,0) -> 9 | L21: =SUMSQ(E21:H21) -> 0.30346666 | M21: =1-(L21-0.25)/0.75 -> 0.92871112 | N21: =RANK(M21,$M$12:$M$24,0) -> 4 | O21: =INDEX($E$11:$H$11,MATCH(MAX(E21:H21),E21:H21,0)) -> Serviços | P21: =MAX(E21:H21) -> 0.38438594 | Q21: =RANK(B21,$B$12:$B$24,0) -> 10 | R21: =RANK(C21,$C$12:$C$24,0) -> 9 | S21: =RANK(D21,$D$12:$D$24,0) -> 4 | V21: =B21-ROW()*0.000000001 -> 0.50659998 | W21: =C21-ROW()*0.000000001 -> 0.59469998 | X21: =D21-ROW()*0.000000001 -> 1.1034 | Y21: =J21-ROW()*0.000000001 -> 0.24940625 | Z21: =M21-ROW()*0.000000001 -> 0.9287111
A22: Porto Esperidião | B22: ='Indicadores (F-W)'!AH6 -> 1.0048 | C22: ='Indicadores (F-W)'!AH11 -> 1.0107 | D22: ='Indicadores (F-W)'!AH14 -> 0.505 | E22: =B22*$B$5 -> 0.38159189 | F22: =C22*$B$6 -> 0.15461385 | G22: =D22*$B$7 -> 0.17592432 | H22: ='Indicadores (F-W)'!AH18/100 -> 0.2879 | I22: =SUM(E22:H22) -> 1.0000301 | J22: =0.5*(ABS(E22-$B$5)+ABS(F22-$B$6)+ABS(G22-$B$7)+ABS(H22-$B$8)) -> 0.17245621 | K22: =RANK(J22,$J$12:$J$24,0) -> 13 | L22: =SUMSQ(E22:H22) -> 0.28335359 | M22: =1-(L22-0.25)/0.75 -> 0.95552854 | N22: =RANK(M22,$M$12:$M$24,0) -> 2 | O22: =INDEX($E$11:$H$11,MATCH(MAX(E22:H22),E22:H22,0)) -> Agropecuária | P22: =MAX(E22:H22) -> 0.38159189 | Q22: =RANK(B22,$B$12:$B$24,0) -> 7 | R22: =RANK(C22,$C$12:$C$24,0) -> 7 | S22: =RANK(D22,$D$12:$D$24,0) -> 6 | V22: =B22-ROW()*0.000000001 -> 1.0048 | W22: =C22-ROW()*0.000000001 -> 1.0107 | X22: =D22-ROW()*0.000000001 -> 0.50499998 | Y22: =J22-ROW()*0.000000001 -> 0.17245619 | Z22: =M22-ROW()*0.000000001 -> 0.95552852
A23: Rondonópolis | B23: ='Indicadores (F-W)'!AJ6 -> 0.1067 | C23: ='Indicadores (F-W)'!AJ11 -> 1.8691 | D23: ='Indicadores (F-W)'!AJ14 -> 1.5988 | E23: =B23*$B$5 -> 0.040521352 | F23: =C23*$B$6 -> 0.28592931 | G23: =D23*$B$7 -> 0.55696596 | H23: ='Indicadores (F-W)'!AJ18/100 -> 0.1166 | I23: =SUM(E23:H23) -> 1.0000166 | J23: =0.5*(ABS(E23-$B$5)+ABS(F23-$B$6)+ABS(G23-$B$7)+ABS(H23-$B$8)) -> 0.34154446 | K23: =RANK(J23,$J$12:$J$24,0) -> 1 | L23: =SUMSQ(E23:H23) -> 0.40720419 | M23: =1-(L23-0.25)/0.75 -> 0.79039441 | N23: =RANK(M23,$M$12:$M$24,0) -> 11 | O23: =INDEX($E$11:$H$11,MATCH(MAX(E23:H23),E23:H23,0)) -> Serviços | P23: =MAX(E23:H23) -> 0.55696596 | Q23: =RANK(B23,$B$12:$B$24,0) -> 13 | R23: =RANK(C23,$C$12:$C$24,0) -> 2 | S23: =RANK(D23,$D$12:$D$24,0) -> 1 | V23: =B23-ROW()*0.000000001 -> 0.10669998 | W23: =C23-ROW()*0.000000001 -> 1.8691 | X23: =D23-ROW()*0.000000001 -> 1.5988 | Y23: =J23-ROW()*0.000000001 -> 0.34154444 | Z23: =M23-ROW()*0.000000001 -> 0.79039439
A24: Santo Antônio do Leverger | B24: ='Indicadores (F-W)'!AL6 -> 1.714 | C24: ='Indicadores (F-W)'!AL11 -> 0.4719 | D24: ='Indicadores (F-W)'!AL14 -> 0.3417 | E24: =B24*$B$5 -> 0.65092407 | F24: =C24*$B$6 -> 0.072189846 | G24: =D24*$B$7 -> 0.11903632 | H24: ='Indicadores (F-W)'!AL18/100 -> 0.1578 | I24: =SUM(E24:H24) -> 0.99995023 | J24: =0.5*(ABS(E24-$B$5)+ABS(F24-$B$6)+ABS(G24-$B$7)+ABS(H24-$B$8)) -> 0.31009145 | K24: =RANK(J24,$J$12:$J$24,0) -> 3 | L24: =SUMSQ(E24:H24) -> 0.467984 | M24: =1-(L24-0.25)/0.75 -> 0.70935467 | N24: =RANK(M24,$M$12:$M$24,0) -> 13 | O24: =INDEX($E$11:$H$11,MATCH(MAX(E24:H24),E24:H24,0)) -> Agropecuária | P24: =MAX(E24:H24) -> 0.65092407 | Q24: =RANK(B24,$B$12:$B$24,0) -> 1 | R24: =RANK(C24,$C$12:$C$24,0) -> 10 | S24: =RANK(D24,$D$12:$D$24,0) -> 12 | V24: =B24-ROW()*0.000000001 -> 1.714 | W24: =C24-ROW()*0.000000001 -> 0.47189998 | X24: =D24-ROW()*0.000000001 -> 0.34169998 | Y24: =J24-ROW()*0.000000001 -> 0.31009143 | Z24: =M24-ROW()*0.000000001 -> 0.70935464
A27: RANKING DE ESPECIALIZAÇÃO POR SETOR (ordenado pelo QL)
A28: AGROPECUÁRIA | F28: INDÚSTRIA | K28: SERVIÇOS (exceto adm. pública)
A29: Pos. | B29: Município | C29: QL | D29: Classificação | F29: Pos. | G29: Município | H29: QL | I29: Classificação | K29: Pos. | L29: Município | M29: QL | N29: Classificação
A30: 1 | B30: =INDEX($A$12:$A$24,MATCH(LARGE($V$12:$V$24,1),$V$12:$V$24,0)) -> Santo Antônio do Leverger | C30: =INDEX($B$12:$B$24,MATCH(LARGE($V$12:$V$24,1),$V$12:$V$24,0)) -> 1.714 | D30: =IF(C30>'Indicadores (F-W)'!$M$6,"Especializado",IF(C30<'Indicadores (F-W)'!$L$6,"Sub-representado","Intermediário")) -> Especializado | F30: 1 | G30: =INDEX($A$12:$A$24,MATCH(LARGE($W$12:$W$24,1),$W$12:$W$24,0)) -> Nossa Senhora do Livramento | H30: =INDEX($C$12:$C$24,MATCH(LARGE($W$12:$W$24,1),$W$12:$W$24,0)) -> 2.0033 | I30: =IF(H30>'Indicadores (F-W)'!$M$11,"Especializado",IF(H30<'Indicadores (F-W)'!$L$11,"Sub-representado","Intermediário")) -> Especializado | K30: 1 | L30: =INDEX($A$12:$A$24,MATCH(LARGE($X$12:$X$24,1),$X$12:$X$24,0)) -> Rondonópolis | M30: =INDEX($D$12:$D$24,MATCH(LARGE($X$12:$X$24,1),$X$12:$X$24,0)) -> 1.5988 | N30: =IF(M30>'Indicadores (F-W)'!$M$14,"Especializado",IF(M30<'Indicadores (F-W)'!$L$14,"Sub-representado","Intermediário")) -> Especializado
A31: 2 | B31: =INDEX($A$12:$A$24,MATCH(LARGE($V$12:$V$24,2),$V$12:$V$24,0)) -> Itiquira | C31: =INDEX($B$12:$B$24,MATCH(LARGE($V$12:$V$24,2),$V$12:$V$24,0)) -> 1.6266 | D31: =IF(C31>'Indicadores (F-W)'!$M$6,"Especializado",IF(C31<'Indicadores (F-W)'!$L$6,"Sub-representado","Intermediário")) -> Especializado | F31: 2 | G31: =INDEX($A$12:$A$24,MATCH(LARGE($W$12:$W$24,2),$W$12:$W$24,0)) -> Rondonópolis | H31: =INDEX($C$12:$C$24,MATCH(LARGE($W$12:$W$24,2),$W$12:$W$24,0)) -> 1.8691 | I31: =IF(H31>'Indicadores (F-W)'!$M$11,"Especializado",IF(H31<'Indicadores (F-W)'!$L$11,"Sub-representado","Intermediário")) -> Especializado | K31: 2 | L31: =INDEX($A$12:$A$24,MATCH(LARGE($X$12:$X$24,2),$X$12:$X$24,0)) -> Cáceres | M31: =INDEX($D$12:$D$24,MATCH(LARGE($X$12:$X$24,2),$X$12:$X$24,0)) -> 1.3013 | N31: =IF(M31>'Indicadores (F-W)'!$M$14,"Especializado",IF(M31<'Indicadores (F-W)'!$L$14,"Sub-representado","Intermediário")) -> Especializado
A32: 3 | B32: =INDEX($A$12:$A$24,MATCH(LARGE($V$12:$V$24,3),$V$12:$V$24,0)) -> Glória D'Oeste | C32: =INDEX($B$12:$B$24,MATCH(LARGE($V$12:$V$24,3),$V$12:$V$24,0)) -> 1.3866 | D32: =IF(C32>'Indicadores (F-W)'!$M$6,"Especializado",IF(C32<'Indicadores (F-W)'!$L$6,"Sub-representado","Intermediário")) -> Especializado | F32: 3 | G32: =INDEX($A$12:$A$24,MATCH(LARGE($W$12:$W$24,3),$W$12:$W$24,0)) -> Itiquira | H32: =INDEX($C$12:$C$24,MATCH(LARGE($W$12:$W$24,3),$W$12:$W$24,0)) -> 1.2891 | I32: =IF(H32>'Indicadores (F-W)'!$M$11,"Especializado",IF(H32<'Indicadores (F-W)'!$L$11,"Sub-representado","Intermediário")) -> Especializado | K32: 3 | L32: =INDEX($A$12:$A$24,MATCH(LARGE($X$12:$X$24,3),$X$12:$X$24,0)) -> Mirassol D'Oeste | M32: =INDEX($D$12:$D$24,MATCH(LARGE($X$12:$X$24,3),$X$12:$X$24,0)) -> 1.1498 | N32: =IF(M32>'Indicadores (F-W)'!$M$14,"Especializado",IF(M32<'Indicadores (F-W)'!$L$14,"Sub-representado","Intermediário")) -> Intermediário
A33: 4 | B33: =INDEX($A$12:$A$24,MATCH(LARGE($V$12:$V$24,4),$V$12:$V$24,0)) -> Lambari D'Oeste | C33: =INDEX($B$12:$B$24,MATCH(LARGE($V$12:$V$24,4),$V$12:$V$24,0)) -> 1.364 | D33: =IF(C33>'Indicadores (F-W)'!$M$6,"Especializado",IF(C33<'Indicadores (F-W)'!$L$6,"Sub-representado","Intermediário")) -> Especializado | F33: 4 | G33: =INDEX($A$12:$A$24,MATCH(LARGE($W$12:$W$24,4),$W$12:$W$24,0)) -> Mirassol D'Oeste | H33: =INDEX($C$12:$C$24,MATCH(LARGE($W$12:$W$24,4),$W$12:$W$24,0)) -> 1.2112 | I33: =IF(H33>'Indicadores (F-W)'!$M$11,"Especializado",IF(H33<'Indicadores (F-W)'!$L$11,"Sub-representado","Intermediário")) -> Especializado | K33: 4 | L33: =INDEX($A$12:$A$24,MATCH(LARGE($X$12:$X$24,4),$X$12:$X$24,0)) -> Poconé | M33: =INDEX($D$12:$D$24,MATCH(LARGE($X$12:$X$24,4),$X$12:$X$24,0)) -> 1.1034 | N33: =IF(M33>'Indicadores (F-W)'!$M$14,"Especializado",IF(M33<'Indicadores (F-W)'!$L$14,"Sub-representado","Intermediário")) -> Intermediário
A34: 5 | B34: =INDEX($A$12:$A$24,MATCH(LARGE($V$12:$V$24,5),$V$12:$V$24,0)) -> Juscimeira | C34: =INDEX($B$12:$B$24,MATCH(LARGE($V$12:$V$24,5),$V$12:$V$24,0)) -> 1.319 | D34: =IF(C34>'Indicadores (F-W)'!$M$6,"Especializado",IF(C34<'Indicadores (F-W)'!$L$6,"Sub-representado","Intermediário")) -> Especializado | F34: 5 | G34: =INDEX($A$12:$A$24,MATCH(LARGE($W$12:$W$24,5),$W$12:$W$24,0)) -> Lambari D'Oeste | H34: =INDEX($C$12:$C$24,MATCH(LARGE($W$12:$W$24,5),$W$12:$W$24,0)) -> 1.1956 | I34: =IF(H34>'Indicadores (F-W)'!$M$11,"Especializado",IF(H34<'Indicadores (F-W)'!$L$11,"Sub-representado","Intermediário")) -> Intermediário | K34: 5 | L34: =INDEX($A$12:$A$24,MATCH(LARGE($X$12:$X$24,5),$X$12:$X$24,0)) -> Nossa Senhora do Livramento | M34: =INDEX($D$12:$D$24,MATCH(LARGE($X$12:$X$24,5),$X$12:$X$24,0)) -> 0.7089 | N34: =IF(M34>'Indicadores (F-W)'!$M$14,"Especializado",IF(M34<'Indicadores (F-W)'!$L$14,"Sub-representado","Intermediário")) -> Sub-representado
A35: 6 | B35: =INDEX($A$12:$A$24,MATCH(LARGE($V$12:$V$24,6),$V$12:$V$24,0)) -> Curvelândia | C35: =INDEX($B$12:$B$24,MATCH(LARGE($V$12:$V$24,6),$V$12:$V$24,0)) -> 1.2022 | D35: =IF(C35>'Indicadores (F-W)'!$M$6,"Especializado",IF(C35<'Indicadores (F-W)'!$L$6,"Sub-representado","Intermediário")) -> Especializado | F35: 6 | G35: =INDEX($A$12:$A$24,MATCH(LARGE($W$12:$W$24,6),$W$12:$W$24,0)) -> Juscimeira | H35: =INDEX($C$12:$C$24,MATCH(LARGE($W$12:$W$24,6),$W$12:$W$24,0)) -> 1.1671 | I35: =IF(H35>'Indicadores (F-W)'!$M$11,"Especializado",IF(H35<'Indicadores (F-W)'!$L$11,"Sub-representado","Intermediário")) -> Intermediário | K35: 6 | L35: =INDEX($A$12:$A$24,MATCH(LARGE($X$12:$X$24,6),$X$12:$X$24,0)) -> Porto Esperidião | M35: =INDEX($D$12:$D$24,MATCH(LARGE($X$12:$X$24,6),$X$12:$X$24,0)) -> 0.505 | N35: =IF(M35>'Indicadores (F-W)'!$M$14,"Especializado",IF(M35<'Indicadores (F-W)'!$L$14,"Sub-representado","Intermediário")) -> Sub-representado
A36: 7 | B36: =INDEX($A$12:$A$24,MATCH(LARGE($V$12:$V$24,7),$V$12:$V$24,0)) -> Porto Esperidião | C36: =INDEX($B$12:$B$24,MATCH(LARGE($V$12:$V$24,7),$V$12:$V$24,0)) -> 1.0048 | D36: =IF(C36>'Indicadores (F-W)'!$M$6,"Especializado",IF(C36<'Indicadores (F-W)'!$L$6,"Sub-representado","Intermediário")) -> Intermediário | F36: 7 | G36: =INDEX($A$12:$A$24,MATCH(LARGE($W$12:$W$24,7),$W$12:$W$24,0)) -> Porto Esperidião | H36: =INDEX($C$12:$C$24,MATCH(LARGE($W$12:$W$24,7),$W$12:$W$24,0)) -> 1.0107 | I36: =IF(H36>'Indicadores (F-W)'!$M$11,"Especializado",IF(H36<'Indicadores (F-W)'!$L$11,"Sub-representado","Intermediário")) -> Intermediário | K36: 7 | L36: =INDEX($A$12:$A$24,MATCH(LARGE($X$12:$X$24,7),$X$12:$X$24,0)) -> Curvelândia | M36: =INDEX($D$12:$D$24,MATCH(LARGE($X$12:$X$24,7),$X$12:$X$24,0)) -> 0.5029 | N36: =IF(M36>'Indicadores (F-W)'!$M$14,"Especializado",IF(M36<'Indicadores (F-W)'!$L$14,"Sub-representado","Intermediário")) -> Sub-representado
A37: 8 | B37: =INDEX($A$12:$A$24,MATCH(LARGE($V$12:$V$24,8),$V$12:$V$24,0)) -> Barão de Melgaço | C37: =INDEX($B$12:$B$24,MATCH(LARGE($V$12:$V$24,8),$V$12:$V$24,0)) -> 0.9631 | D37: =IF(C37>'Indicadores (F-W)'!$M$6,"Especializado",IF(C37<'Indicadores (F-W)'!$L$6,"Sub-representado","Intermediário")) -> Intermediário | F37: 8 | G37: =INDEX($A$12:$A$24,MATCH(LARGE($W$12:$W$24,8),$W$12:$W$24,0)) -> Cáceres | H37: =INDEX($C$12:$C$24,MATCH(LARGE($W$12:$W$24,8),$W$12:$W$24,0)) -> 0.6374 | I37: =IF(H37>'Indicadores (F-W)'!$M$11,"Especializado",IF(H37<'Indicadores (F-W)'!$L$11,"Sub-representado","Intermediário")) -> Sub-representado | K37: 8 | L37: =INDEX($A$12:$A$24,MATCH(LARGE($X$12:$X$24,8),$X$12:$X$24,0)) -> Glória D'Oeste | M37: =INDEX($D$12:$D$24,MATCH(LARGE($X$12:$X$24,8),$X$12:$X$24,0)) -> 0.4636 | N37: =IF(M37>'Indicadores (F-W)'!$M$14,"Especializado",IF(M37<'Indicadores (F-W)'!$L$14,"Sub-representado","Intermediário")) -> Sub-representado
A38: 9 | B38: =INDEX($A$12:$A$24,MATCH(LARGE($V$12:$V$24,9),$V$12:$V$24,0)) -> Nossa Senhora do Livramento | C38: =INDEX($B$12:$B$24,MATCH(LARGE($V$12:$V$24,9),$V$12:$V$24,0)) -> 0.5183 | D38: =IF(C38>'Indicadores (F-W)'!$M$6,"Especializado",IF(C38<'Indicadores (F-W)'!$L$6,"Sub-representado","Intermediário")) -> Sub-representado | F38: 9 | G38: =INDEX($A$12:$A$24,MATCH(LARGE($W$12:$W$24,9),$W$12:$W$24,0)) -> Poconé | H38: =INDEX($C$12:$C$24,MATCH(LARGE($W$12:$W$24,9),$W$12:$W$24,0)) -> 0.5947 | I38: =IF(H38>'Indicadores (F-W)'!$M$11,"Especializado",IF(H38<'Indicadores (F-W)'!$L$11,"Sub-representado","Intermediário")) -> Sub-representado | K38: 9 | L38: =INDEX($A$12:$A$24,MATCH(LARGE($X$12:$X$24,9),$X$12:$X$24,0)) -> Juscimeira | M38: =INDEX($D$12:$D$24,MATCH(LARGE($X$12:$X$24,9),$X$12:$X$24,0)) -> 0.4388 | N38: =IF(M38>'Indicadores (F-W)'!$M$14,"Especializado",IF(M38<'Indicadores (F-W)'!$L$14,"Sub-representado","Intermediário")) -> Sub-representado
A39: 10 | B39: =INDEX($A$12:$A$24,MATCH(LARGE($V$12:$V$24,10),$V$12:$V$24,0)) -> Poconé | C39: =INDEX($B$12:$B$24,MATCH(LARGE($V$12:$V$24,10),$V$12:$V$24,0)) -> 0.5066 | D39: =IF(C39>'Indicadores (F-W)'!$M$6,"Especializado",IF(C39<'Indicadores (F-W)'!$L$6,"Sub-representado","Intermediário")) -> Sub-representado | F39: 10 | G39: =INDEX($A$12:$A$24,MATCH(LARGE($W$12:$W$24,10),$W$12:$W$24,0)) -> Santo Antônio do Leverger | H39: =INDEX($C$12:$C$24,MATCH(LARGE($W$12:$W$24,10),$W$12:$W$24,0)) -> 0.4719 | I39: =IF(H39>'Indicadores (F-W)'!$M$11,"Especializado",IF(H39<'Indicadores (F-W)'!$L$11,"Sub-representado","Intermediário")) -> Sub-representado | K39: 10 | L39: =INDEX($A$12:$A$24,MATCH(LARGE($X$12:$X$24,10),$X$12:$X$24,0)) -> Barão de Melgaço | M39: =INDEX($D$12:$D$24,MATCH(LARGE($X$12:$X$24,10),$X$12:$X$24,0)) -> 0.4274 | N39: =IF(M39>'Indicadores (F-W)'!$M$14,"Especializado",IF(M39<'Indicadores (F-W)'!$L$14,"Sub-representado","Intermediário")) -> Sub-representado
A40: 11 | B40: =INDEX($A$12:$A$24,MATCH(LARGE($V$12:$V$24,11),$V$12:$V$24,0)) -> Mirassol D'Oeste | C40: =INDEX($B$12:$B$24,MATCH(LARGE($V$12:$V$24,11),$V$12:$V$24,0)) -> 0.416 | D40: =IF(C40>'Indicadores (F-W)'!$M$6,"Especializado",IF(C40<'Indicadores (F-W)'!$L$6,"Sub-representado","Intermediário")) -> Sub-representado | F40: 11 | G40: =INDEX($A$12:$A$24,MATCH(LARGE($W$12:$W$24,11),$W$12:$W$24,0)) -> Curvelândia | H40: =INDEX($C$12:$C$24,MATCH(LARGE($W$12:$W$24,11),$W$12:$W$24,0)) -> 0.4717 | I40: =IF(H40>'Indicadores (F-W)'!$M$11,"Especializado",IF(H40<'Indicadores (F-W)'!$L$11,"Sub-representado","Intermediário")) -> Sub-representado | K40: 11 | L40: =INDEX($A$12:$A$24,MATCH(LARGE($X$12:$X$24,11),$X$12:$X$24,0)) -> Itiquira | M40: =INDEX($D$12:$D$24,MATCH(LARGE($X$12:$X$24,11),$X$12:$X$24,0)) -> 0.3623 | N40: =IF(M40>'Indicadores (F-W)'!$M$14,"Especializado",IF(M40<'Indicadores (F-W)'!$L$14,"Sub-representado","Intermediário")) -> Sub-representado
A41: 12 | B41: =INDEX($A$12:$A$24,MATCH(LARGE($V$12:$V$24,12),$V$12:$V$24,0)) -> Cáceres | C41: =INDEX($B$12:$B$24,MATCH(LARGE($V$12:$V$24,12),$V$12:$V$24,0)) -> 0.3713 | D41: =IF(C41>'Indicadores (F-W)'!$M$6,"Especializado",IF(C41<'Indicadores (F-W)'!$L$6,"Sub-representado","Intermediário")) -> Sub-representado | F41: 12 | G41: =INDEX($A$12:$A$24,MATCH(LARGE($W$12:$W$24,12),$W$12:$W$24,0)) -> Glória D'Oeste | H41: =INDEX($C$12:$C$24,MATCH(LARGE($W$12:$W$24,12),$W$12:$W$24,0)) -> 0.2854 | I41: =IF(H41>'Indicadores (F-W)'!$M$11,"Especializado",IF(H41<'Indicadores (F-W)'!$L$11,"Sub-representado","Intermediário")) -> Sub-representado | K41: 12 | L41: =INDEX($A$12:$A$24,MATCH(LARGE($X$12:$X$24,12),$X$12:$X$24,0)) -> Santo Antônio do Leverger | M41: =INDEX($D$12:$D$24,MATCH(LARGE($X$12:$X$24,12),$X$12:$X$24,0)) -> 0.3417 | N41: =IF(M41>'Indicadores (F-W)'!$M$14,"Especializado",IF(M41<'Indicadores (F-W)'!$L$14,"Sub-representado","Intermediário")) -> Sub-representado
A42: 13 | B42: =INDEX($A$12:$A$24,MATCH(LARGE($V$12:$V$24,13),$V$12:$V$24,0)) -> Rondonópolis | C42: =INDEX($B$12:$B$24,MATCH(LARGE($V$12:$V$24,13),$V$12:$V$24,0)) -> 0.1067 | D42: =IF(C42>'Indicadores (F-W)'!$M$6,"Especializado",IF(C42<'Indicadores (F-W)'!$L$6,"Sub-representado","Intermediário")) -> Sub-representado | F42: 13 | G42: =INDEX($A$12:$A$24,MATCH(LARGE($W$12:$W$24,13),$W$12:$W$24,0)) -> Barão de Melgaço | H42: =INDEX($C$12:$C$24,MATCH(LARGE($W$12:$W$24,13),$W$12:$W$24,0)) -> 0.169 | I42: =IF(H42>'Indicadores (F-W)'!$M$11,"Especializado",IF(H42<'Indicadores (F-W)'!$L$11,"Sub-representado","Intermediário")) -> Sub-representado | K42: 13 | L42: =INDEX($A$12:$A$24,MATCH(LARGE($X$12:$X$24,13),$X$12:$X$24,0)) -> Lambari D'Oeste | M42: =INDEX($D$12:$D$24,MATCH(LARGE($X$12:$X$24,13),$X$12:$X$24,0)) -> 0.3227 | N42: =IF(M42>'Indicadores (F-W)'!$M$14,"Especializado",IF(M42<'Indicadores (F-W)'!$L$14,"Sub-representado","Intermediário")) -> Sub-representado
A45: RANKING DE ESPECIALIZAÇÃO GERAL E DE DIVERSIFICAÇÃO
A46: COEFICIENTE DE ESPECIALIZAÇÃO (maior = estrutura mais distante de MT) | F46: DIVERSIFICAÇÃO (maior = menos dependente de um setor)
...

Sheet Ranking SWOT (provisório)
A1: ⚠ RANKING SWOT — COBERTURA MÍNIMA ATINGIDA; NOTAS EXTERNAS A VALIDAR
A2: A regra de 75% de cobertura foi atingida em 25/09/2026: 14 de 16 indicadores internos com dado e 11 de 11 fatores externos pontuados. As notas externas ainda são preliminares (uma rodada, pesquisa web-based) e precisam de consenso da equipe antes de uso em relatório.
A4: Município | B4: Forças | C4: Fraquezas | D4: Indicadores com dado | E4: Cobertura interna | F4: Índice interno (F−W)/n | G4: Oportunidades | H4: Ameaças | I4: Fatores pontuados | J4: Cobertura externa | K4: Índice externo (O−T)/n | L4: Índice SWOT | M4: Posição | N4: Status
